Exception in Tkinter callback
Traceback (most recent call last):
  File "C:\Users\Pc\Anaconda3\lib\site-packages\mysql\connector\connection_cext.py", line 472, in cmd_query
    raw_as_string=raw_as_string)
_mysql_connector.MySQLInterfaceError: Duplicate entry '2' for key 'PRIMARY'

During handling of the above exception, another exception occurred:

Traceback (most recent call last):
  File "C:\Users\Pc\Anaconda3\lib\tkinter\__init__.py", line 1705, in __call__
    return self.func(*args)
  File "C:\Users\Pc\Documents\GitHub\HMS\doc_entry_support.py", line 38, in doc_submit
    c.execute(sqlstat,task)
  File "C:\Users\Pc\Anaconda3\lib\site-packages\mysql\connector\cursor_cext.py", line 266, in execute
    raw_as_string=self._raw_as_string)
  File "C:\Users\Pc\Anaconda3\lib\site-packages\mysql\connector\connection_cext.py", line 475, in cmd_query
    sqlstate=exc.sqlstate)
mysql.connector.errors.IntegrityError: 1062 (23000): Duplicate entry '2' for key 'PRIMARY'
